
record _Unwind_Exception {
    exception_class: Int32;
    exception_cleanup: CodePointer[Int32, Pointer[_Unwind_Exception], Void];    
    private_1: Int32;
    private_2: Int32;
}

external _Unwind_RaiseException(p:Pointer[_Unwind_Exception]) Int32;

throw() {
    var exception = allocateMemory(_Unwind_Exception, 1);
    println("Throwing");
    _Unwind_RaiseException(exception); 
}

record Test {
    x: Int32;
}

overload destroy(t:Test) {
    println("Destroyed ", t.x);
}

m(x) {
    try {
        var r = Test(1);
        if (x == 1)
            throw();
        var r2 = Test(2);
    } catch {
        println("Caught. Throwing again.");
        throw();
    }
    var r2 = Test(3);
}

main() {
    try {
        println("Hello World");
        m(0);
        var r = Test(20);
        m(1);
        var r = Test(30);
    } catch {
        println("Caught");
    }
    return 0;
}
